Workbook

Sheet employees
A1: employee_id | B1: name | C1: gender | D1: age | E1: department_id | F1: department_name | G1: department_category | H1: location_id | I1: City | J1: Continent | K1: seniority | L1: education | M1: hire_date | N1: work_mode | O1: performance_score | P1: satisfaction_score | Q1: initial_salary_usd | R1: manager_id | S1: Tenure | T1: cost_index | U1: Cost Adjusted Salary
A2: 1 | B2: Allison Hill | C2: Male | D2: 34 | E2: 21 | F2: =VLOOKUP(Table6[[#This Row],[department_id]],departments[#All],2,FALSE) -> Finance | G2: =VLOOKUP(employees!$E2,departments[],3,FALSE) -> G&A | H2: 4 | I2: =VLOOKUP(employees!$H2,locations[#All],3,FALSE) -> Toronto | J2: =_xlfn.XLOOKUP(Table6[[#This Row],[City]],locations[city],locations[Continent]) -> North America | K2: Intern | L2: Bachelor | M2: 43893 | N2: On-site | O2: 4.2 | P2: 7.6 | Q2: 39578.39 | R2: 2177 | S2: =DATEDIF(employees!$M2, TODAY(), "y") -> 6 | T2: =VLOOKUP(employees!$H2,locations[#All],4,) -> 1.1 | U2: =employees!$Q2/employees!$T2 -> 35980.355
A3: 2 | B3: Noah Rhodes | C3: Non-binary | D3: 32 | E3: 3 | F3: =VLOOKUP(Table6[[#This Row],[department_id]],departments[#All],2,FALSE) -> Data Engineering | G3: =VLOOKUP(employees!$E3,departments[],3,FALSE) -> Tech | H3: 7 | I3: =VLOOKUP(employees!$H3,locations[#All],3,FALSE) -> Paris | J3: =_xlfn.XLOOKUP(Table6[[#This Row],[City]],locations[city],locations[Continent]) -> Europe | K3: Mid | L3: Master | M3: 41857 | N3: Hybrid | O3: 3.46 | P3: 7.2 | Q3: 141489.28 | R3: 2225 | S3: =DATEDIF(employees!$M3, TODAY(), "y") -> 12 | T3: =VLOOKUP(employees!$H3,locations[#All],4,) -> 1.18 | U3: =employees!$Q3/employees!$T3 -> 119906.17
A4: 3 | B4: Angie Henderson | C4: Female | D4: 29 | E4: 25 | F4: =VLOOKUP(Table6[[#This Row],[department_id]],departments[#All],2,FALSE) -> Operations | G4: =VLOOKUP(employees!$E4,departments[],3,FALSE) -> Ops | H4: 6 | I4: =VLOOKUP(employees!$H4,locations[#All],3,FALSE) -> Berlin | J4: =_xlfn.XLOOKUP(Table6[[#This Row],[City]],locations[city],locations[Continent]) -> Europe | K4: Senior | L4: Bachelor | M4: 44427 | N4: Hybrid | O4: 2.74 | P4: 6.8 | Q4: 104066.61 | R4: 43 | S4: =DATEDIF(employees!$M4, TODAY(), "y") -> 5 | T4: =VLOOKUP(employees!$H4,locations[#All],4,) -> 1.1 | U4: =employees!$Q4/employees!$T4 -> 94606.009
A5: 4 | B5: Daniel Wagner | C5: Female | D5: 25 | E5: 9 | F5: =VLOOKUP(Table6[[#This Row],[department_id]],departments[#All],2,FALSE) -> Product Management | G5: =VLOOKUP(employees!$E5,departments[],3,FALSE) -> Product | H5: 2 | I5: =VLOOKUP(employees!$H5,locations[#All],3,FALSE) -> New York | J5: =_xlfn.XLOOKUP(Table6[[#This Row],[City]],locations[city],locations[Continent]) -> North America | K5: Senior | L5: Bachelor | M5: 42662 | N5: Remote | O5: 3.92 | P5: 9.1 | Q5: 238113.44 | R5: 290 | S5: =DATEDIF(employees!$M5, TODAY(), "y") -> 9 | T5: =VLOOKUP(employees!$H5,locations[#All],4,) -> 1.3 | U5: =employees!$Q5/employees!$T5 -> 183164.18
A6: 5 | B6: Cristian Santos | C6: Male | D6: 26 | E6: 2 | F6: =VLOOKUP(Table6[[#This Row],[department_id]],departments[#All],2,FALSE) -> Data Science | G6: =VLOOKUP(employees!$E6,departments[],3,FALSE) -> Tech | H6: 8 | I6: =VLOOKUP(employees!$H6,locations[#All],3,FALSE) -> Barcelona | J6: =_xlfn.XLOOKUP(Table6[[#This Row],[City]],locations[city],locations[Continent]) -> Europe | K6: Lead | L6: Bachelor | M6: 42293 | N6: Hybrid | O6: 4.42 | P6: 5.8 | Q6: 212557.11 | R6: 1603 | S6: =DATEDIF(employees!$M6, TODAY(), "y") -> 10 | T6: =VLOOKUP(employees!$H6,locations[#All],4,) -> 1.05 | U6: =employees!$Q6/employees!$T6 -> 202435.34
A7: 6 | B7: Connie Lawrence | C7: Non-binary | D7: 35 | E7: 23 | F7: =VLOOKUP(Table6[[#This Row],[department_id]],departments[#All],2,FALSE) -> Legal | G7: =VLOOKUP(employees!$E7,departments[],3,FALSE) -> G&A | H7: 21 | I7: =VLOOKUP(employees!$H7,locations[#All],3,FALSE) -> Sydney | J7: =_xlfn.XLOOKUP(Table6[[#This Row],[City]],locations[city],locations[Continent]) -> Oceania | K7: Junior | L7: Bachelor | M7: 43041 | N7: Hybrid | O7: 4.78 | P7: 8.1 | Q7: 131834.83 | R7: 2865 | S7: =DATEDIF(employees!$M7, TODAY(), "y") -> 8 | T7: =VLOOKUP(employees!$H7,locations[#All],4,) -> 1.15 | U7: =employees!$Q7/employees!$T7 -> 114638.98
A8: 7 | B8: Abigail Shaffer | C8: Female | D8: 45 | E8: 27 | F8: =VLOOKUP(Table6[[#This Row],[department_id]],departments[#All],2,FALSE) -> Facilities | G8: =VLOOKUP(employees!$E8,departments[],3,FALSE) -> Ops | H8: 2 | I8: =VLOOKUP(employees!$H8,locations[#All],3,FALSE) -> New York | J8: =_xlfn.XLOOKUP(Table6[[#This Row],[City]],locations[city],locations[Continent]) -> North America | K8: Mid | L8: Bachelor | M8: 41902 | N8: On-site | O8: 4.67 | P8: 9.2 | Q8: 72613.77 | R8: 778 | S8: =DATEDIF(employees!$M8, TODAY(), "y") -> 11 | T8: =VLOOKUP(employees!$H8,locations[#All],4,) -> 1.3 | U8: =employees!$Q8/employees!$T8 -> 55856.746
A9: 8 | B9: Gina Moore | C9: Male | D9: 35 | E9: 13 | F9: =VLOOKUP(Table6[[#This Row],[department_id]],departments[#All],2,FALSE) -> Sales | G9: =VLOOKUP(employees!$E9,departments[],3,FALSE) -> GTM | H9: 21 | I9: =VLOOKUP(employees!$H9,locations[#All],3,FALSE) -> Sydney | J9: =_xlfn.XLOOKUP(Table6[[#This Row],[City]],locations[city],locations[Continent]) -> Oceania | K9: Mid | L9: Master | M9: 43809 | N9: Hybrid | O9: 4.22 | P9: 7.1 | Q9: 78331.79 | R9: 1834 | S9: =DATEDIF(employees!$M9, TODAY(), "y") -> 6 | T9: =VLOOKUP(employees!$H9,locations[#All],4,) -> 1.15 | U9: =employees!$Q9/employees!$T9 -> 68114.6
A10: 9 | B10: Gabrielle Davis | C10: Male | D10: 29 | E10: 5 | F10: =VLOOKUP(Table6[[#This Row],[department_id]],departments[#All],2,FALSE) -> Platform | G10: =VLOOKUP(employees!$E10,departments[],3,FALSE) -> Tech | H10: 17 | I10: =VLOOKUP(employees!$H10,locations[#All],3,FALSE) -> Mexico City | J10: =_xlfn.XLOOKUP(Table6[[#This Row],[City]],locations[city],locations[Continent]) -> South America | K10: Mid | L10: Bachelor | M10: 42025 | N10: Hybrid | O10: 3.47 | P10: 5.3 | Q10: 109102.46 | R10: 2497 | S10: =DATEDIF(employees!$M10, TODAY(), "y") -> 11 | T10: =VLOOKUP(employees!$H10,locations[#All],4,) -> 0.78 | U10: =employees!$Q10/employees!$T10 -> 139874.95
A11: 10 | B11: Ryan Munoz | C11: Non-binary | D11: 27 | E11: 17 | F11: =VLOOKUP(Table6[[#This Row],[department_id]],departments[#All],2,FALSE) -> Customer Success | G11: =VLOOKUP(employees!$E11,departments[],3,FALSE) -> GTM | H11: 9 | I11: =VLOOKUP(employees!$H11,locations[#All],3,FALSE) -> Amsterdam | J11: =_xlfn.XLOOKUP(Table6[[#This Row],[City]],locations[city],locations[Continent]) -> Europe | K11: Director | L11: Master | M11: 41734 | N11: Hybrid | O11: 3.11 | P11: 8.1 | Q11: 138649.03 | R11: 346 | S11: =DATEDIF(employees!$M11, TODAY(), "y") -> 12 | T11: =VLOOKUP(employees!$H11,locations[#All],4,) -> 1.15 | U11: =employees!$Q11/employees!$T11 -> 120564.37
A12: 11 | B12: Monica Herrera | C12: Non-binary | D12: 31 | E12: 15 | F12: =VLOOKUP(Table6[[#This Row],[department_id]],departments[#All],2,FALSE) -> Marketing | G12: =VLOOKUP(employees!$E12,departments[],3,FALSE) -> GTM | H12: 1 | I12: =VLOOKUP(employees!$H12,locations[#All],3,FALSE) -> San Francisco | J12: =_xlfn.XLOOKUP(Table6[[#This Row],[City]],locations[city],locations[Continent]) -> North America | K12: Director | L12: Bachelor | M12: 43797 | N12: On-site | O12: 3.94 | P12: 9 | Q12: 221539.35 | R12: 2411 | S12: =DATEDIF(employees!$M12, TODAY(), "y") -> 6 | T12: =VLOOKUP(employees!$H12,locations[#All],4,) -> 1.35 | U12: =employees!$Q12/employees!$T12 -> 164103.22
A13: 12 | B13: Jamie Arnold | C13: Non-binary | D13: 40 | E13: 12 | F13: =VLOOKUP(Table6[[#This Row],[department_id]],departments[#All],2,FALSE) -> UX Research | G13: =VLOOKUP(employees!$E13,departments[],3,FALSE) -> Product | H13: 6 | I13: =VLOOKUP(employees!$H13,locations[#All],3,FALSE) -> Berlin | J13: =_xlfn.XLOOKUP(Table6[[#This Row],[City]],locations[city],locations[Continent]) -> Europe | K13: Senior | L13: Bachelor | M13: 41644 | N13: On-site | O13: 3.33 | P13: 9.7 | Q13: 157508.42 | R13: 873 | S13: =DATEDIF(employees!$M13, TODAY(), "y") -> 12 | T13: =VLOOKUP(employees!$H13,locations[#All],4,) -> 1.1 | U13: =employees!$Q13/employees!$T13 -> 143189.47
... A54: 53 | B54: Crystal Robinson | C54: Female | D54: 51 | E54: 3 | F54: =VLOOKUP(Table6[[#This Row],[department_id]],departments[#All],2,FALSE) -> Data Engineering | G54: =VLOOKUP(employees!$E54,departments[],3,FALSE) -> Tech | H54: 17 | I54: =VLOOKUP(employees!$H54,locations[#All],3,FALSE) -> Mexico City | J54: =_xlfn.XLOOKUP(Table6[[#This Row],[City]],locations[city],locations[Continent]) -> South America | K54: Senior | L54: High School | M54: 41743 | N54: Remote | O54: 3.96 | P54: 9 | Q54: 137985.66 | R54: 3249 | S54: =DATEDIF(employees!$M54, TODAY(), "y") -> 12 | T54: =VLOOKUP(employees!$H54,locations[#All],4,) -> 0.78 | U54: =employees!$Q54/employees!$T54 -> 176904.69
A55: 54 | B55: Mark Perez | C55: Non-binary | D55: 54 | E55: 24 | F55: =VLOOKUP(Table6[[#This Row],[department_id]],departments[#All],2,FALSE) -> Administration | G55: =VLOOKUP(employees!$E55,departments[],3,FALSE) -> G&A | H55: 17 | I55: =VLOOKUP(employees!$H55,locations[#All],3,FALSE) -> Mexico City | J55: =_xlfn.XLOOKUP(Table6[[#This Row],[City]],locations[city],locations[Continent]) -> South America | K55: Director | L55: Master | M55: 43852 | N55: Hybrid | O55: 4.4 | P55: 7.8 | Q55: 70413.64 | R55: Unknown | S55: =DATEDIF(employees!$M55, TODAY(), "y") -> 6 | T55: =VLOOKUP(employees!$H55,locations[#All],4,) -> 0.78 | U55: =employees!$Q55/employees!$T55 -> 90273.897
A56: 55 | B56: Shannon Jones | C56: Female | D56: 56 | E56: 3 | F56: =VLOOKUP(Table6[[#This Row],[department_id]],departments[#All],2,FALSE) -> Data Engineering | G56: =VLOOKUP(employees!$E56,departments[],3,FALSE) -> Tech | H56: 9 | I56: =VLOOKUP(employees!$H56,locations[#All],3,FALSE) -> Amsterdam | J56: =_xlfn.XLOOKUP(Table6[[#This Row],[City]],locations[city],locations[Continent]) -> Europe | K56: Manager | L56: Bachelor | M56: 43637 | N56: Hybrid | O56: 2.57 | P56: 9.1 | Q56: 183975.81 | R56: 1040 | S56: =DATEDIF(employees!$M56, TODAY(), "y") -> 7 | T56: =VLOOKUP(employees!$H56,locations[#All],4,) -> 1.15 | U56: =employees!$Q56/employees!$T56 -> 159978.97
A57: 56 | B57: Michael Lewis | C57: Non-binary | D57: 20 | E57: 26 | F57: =VLOOKUP(Table6[[#This Row],[department_id]],departments[#All],2,FALSE) -> Procurement | G57: =VLOOKUP(employees!$E57,departments[],3,FALSE) -> Ops | H57: 9 | I57: =VLOOKUP(employees!$H57,locations[#All],3,FALSE) -> Amsterdam | J57: =_xlfn.XLOOKUP(Table6[[#This Row],[City]],locations[city],locations[Continent]) -> Europe | K57: Mid | L57: Bachelor | M57: 43903 | N57: On-site | O57: 3.06 | P57: 7 | Q57: 88147.69 | R57: 3408 | S57: =DATEDIF(employees!$M57, TODAY(), "y") -> 6 | T57: =VLOOKUP(employees!$H57,locations[#All],4,) -> 1.15 | U57: =employees!$Q57/employees!$T57 -> 76650.165
A58: 57 | B58: Timothy Duncan | C58: Male | D58: 25 | E58: 16 | F58: =VLOOKUP(Table6[[#This Row],[department_id]],departments[#All],2,FALSE) -> Content Marketing | G58: =VLOOKUP(employees!$E58,departments[],3,FALSE) -> GTM | H58: 21 | I58: =VLOOKUP(employees!$H58,locations[#All],3,FALSE) -> Sydney | J58: =_xlfn.XLOOKUP(Table6[[#This Row],[City]],locations[city],locations[Continent]) -> Oceania | K58: Senior | L58: Bachelor | M58: 45311 | N58: Hybrid | O58: 3.06 | P58: 8.2 | Q58: 94763.13 | R58: 3452 | S58: =DATEDIF(employees!$M58, TODAY(), "y") -> 2 | T58: =VLOOKUP(employees!$H58,locations[#All],4,) -> 1.15 | U58: =employees!$Q58/employees!$T58 -> 82402.722
A59: 58 | B59: Richard Aguirre | C59: Female | D59: 64 | E59: 12 | F59: =VLOOKUP(Table6[[#This Row],[department_id]],departments[#All],2,FALSE) -> UX Research | G59: =VLOOKUP(employees!$E59,departments[],3,FALSE) -> Product | H59: 14 | I59: =VLOOKUP(employees!$H59,locations[#All],3,FALSE) -> Dubai | J59: =_xlfn.XLOOKUP(Table6[[#This Row],[City]],locations[city],locations[Continent]) -> Asia | K59: Vp | L59: Bachelor | M59: 44349 | N59: On-site | O59: 3.03 | P59: 8.5 | Q59: 307354.7 | R59: Unknown | S59: =DATEDIF(employees!$M59, TODAY(), "y") -> 5 | T59: =VLOOKUP(employees!$H59,locations[#All],4,) -> 1.05 | U59: =employees!$Q59/employees!$T59 -> 292718.76
A60: 59 | B60: Brent Jordan | C60: Female | D60: 57 | E60: 25 | F60: =VLOOKUP(Table6[[#This Row],[department_id]],departments[#All],2,FALSE) -> Operations | G60: =VLOOKUP(employees!$E60,departments[],3,FALSE) -> Ops | H60: 6 | I60: =VLOOKUP(employees!$H60,locations[#All],3,FALSE) -> Berlin | J60: =_xlfn.XLOOKUP(Table6[[#This Row],[City]],locations[city],locations[Continent]) -> Europe | K60: Junior | L60: PhD | M60: 45606 | N60: Hybrid | O60: 3.15 | P60: 5.5 | Q60: 48276.76 | R60: 3093 | S60: =DATEDIF(employees!$M60, TODAY(), "y") -> 1 | T60: =VLOOKUP(employees!$H60,locations[#All],4,) -> 1.1 | U60: =employees!$Q60/employees!$T60 -> 43887.964
A61: 60 | B61: John Daniel | C61: Female | D61: 22 | E61: 6 | F61: =VLOOKUP(Table6[[#This Row],[department_id]],departments[#All],2,FALSE) -> Security | G61: =VLOOKUP(employees!$E61,departments[],3,FALSE) -> Tech | H61: 10 | I61: =VLOOKUP(employees!$H61,locations[#All],3,FALSE) -> Warsaw | J61: =_xlfn.XLOOKUP(Table6[[#This Row],[City]],locations[city],locations[Continent]) -> Europe | K61: Intern | L61: PhD | M61: 42676 | N61: Hybrid | O61: 4.1 | P61: 5.6 | Q61: 66078.07 | R61: 2919 | S61: =DATEDIF(employees!$M61, TODAY(), "y") -> 9 | T61: =VLOOKUP(employees!$H61,locations[#All],4,) -> 0.95 | U61: =employees!$Q61/employees!$T61 -> 69555.863
A62: 61 | B62: Victoria Garcia | C62: Female | D62: 41 | E62: 1 | F62: =VLOOKUP(Table6[[#This Row],[department_id]],departments[#All],2,FALSE) -> Engineering | G62: =VLOOKUP(employees!$E62,departments[],3,FALSE) -> Tech | H62: 19 | I62: =VLOOKUP(employees!$H62,locations[#All],3,FALSE) -> Tokyo | J62: =_xlfn.XLOOKUP(Table6[[#This Row],[City]],locations[city],locations[Continent]) -> Asia | K62: Mid | L62: Bachelor | M62: 45561 | N62: On-site | O62: 4.66 | P62: 7.3 | Q62: 159527.03 | R62: 1215 | S62: =DATEDIF(employees!$M62, TODAY(), "y") -> 1 | T62: =VLOOKUP(employees!$H62,locations[#All],4,) -> 1.2 | U62: =employees!$Q62/employees!$T62 -> 132939.19
A63: 62 | B63: Gerald Hensley | C63: Male | D63: 29 | E63: 3 | F63: =VLOOKUP(Table6[[#This Row],[department_id]],departments[#All],2,FALSE) -> Data Engineering | G63: =VLOOKUP(employees!$E63,departments[],3,FALSE) -> Tech | H63: 19 | I63: =VLOOKUP(employees!$H63,locations[#All],3,FALSE) -> Tokyo | J63: =_xlfn.XLOOKUP(Table6[[#This Row],[City]],locations[city],locations[Continent]) -> Asia | K63: Senior | L63: Master | M63: 42079 | N63: Remote | O63: 2.7 | P63: 6.2 | Q63: 194246.36 | R63: 903 | S63: =DATEDIF(employees!$M63, TODAY(), "y") -> 11 | T63: =VLOOKUP(employees!$H63,locations[#All],4,) -> 1.2 | U63: =employees!$Q63/employees!$T63 -> 161871.97
A64: 63 | B64: Connor West | C64: Female | D64: 48 | E64: 20 | F64: =VLOOKUP(Table6[[#This Row],[department_id]],departments[#All],2,FALSE) -> Recruiting | G64: =VLOOKUP(employees!$E64,departments[],3,FALSE) -> G&A | H64: 20 | I64: =VLOOKUP(employees!$H64,locations[#All],3,FALSE) -> Singapore | J64: =_xlfn.XLOOKUP(Table6[[#This Row],[City]],locations[city],locations[Continent]) -> Asia | K64: Mid | L64: Master | M64: 45920 | N64: On-site | O64: 3.85 | P64: 7.1 | Q64: 78854.41 | R64: 997 | S64: =DATEDIF(employees!$M64, TODAY(), "y") -> 0 | T64: =VLOOKUP(employees!$H64,locations[#All],4,) -> 1.22 | U64: =employees!$Q64/employees!$T64 -> 64634.762
A65: 64 | B65: Donald Wright | C65: Non-binary | D65: 33 | E65: 24 | F65: =VLOOKUP(Table6[[#This Row],[department_id]],departments[#All],2,FALSE) -> Administration | G65: =VLOOKUP(employees!$E65,departments[],3,FALSE) -> G&A | H65: 4 | I65: =VLOOKUP(employees!$H65,locations[#All],3,FALSE) -> Toronto | J65: =_xlfn.XLOOKUP(Table6[[#This Row],[City]],locations[city],locations[Continent]) -> North America | K65: Manager | L65: Bachelor | M65: 43342 | N65: On-site | O65: 3.05 | P65: 7.6 | Q65: 77825.29 | R65: 311 | S65: =DATEDIF(employees!$M65, TODAY(), "y") -> 8 | T65: =VLOOKUP(employees!$H65,locations[#All],4,) -> 1.1 | U65: =employees!$Q65/employees!$T65 -> 70750.264
A66: 65 | B66: Jessica Callahan | C66: Male | D66: 38 | E66: 23 | F66: =VLOOKUP(Table6[[#This Row],[department_id]],departments[#All],2,FALSE) -> Legal | G66: =VLOOKUP(employees!$E66,departments[],3,FALSE) -> G&A | H66: 20 | I66: =VLOOKUP(employees!$H66,locations[#All],3,FALSE) -> Singapore | J66: =_xlfn.XLOOKUP(Table6[[#This Row],[City]],locations[city],locations[Continent]) -> Asia | K66: Mid | L66: Master | M66: 41907 | N66: Hybrid | O66: 3.54 | P66: 8.3 | Q66: 236083.96 | R66: 3227 | S66: =DATEDIF(employees!$M66, TODAY(), "y") -> 11 | T66: =VLOOKUP(employees!$H66,locations[#All],4,) -> 1.22 | U66: =employees!$Q66/employees!$T66 -> 193511.44
A67: 66 | B67: Amber Kidd | C67: Female | D67: 27 | E67: 21 | F67: =VLOOKUP(Table6[[#This Row],[department_id]],departments[#All],2,FALSE) -> Finance | G67: =VLOOKUP(employees!$E67,departments[],3,FALSE) -> G&A | H67: 19 | I67: =VLOOKUP(employees!$H67,locations[#All],3,FALSE) -> Tokyo | J67: =_xlfn.XLOOKUP(Table6[[#This Row],[City]],locations[city],locations[Continent]) -> Asia | K67: Senior | L67: Bachelor | M67: 43260 | N67: Hybrid | O67: 4.59 | P67: 9 | Q67: 90725.7 | R67: 1229 | S67: =DATEDIF(employees!$M67, TODAY(), "y") -> 8 | T67: =VLOOKUP(employees!$H67,locations[#All],4,) -> 1.2 | U67: =employees!$Q67/employees!$T67 -> 75604.75
A68: 67 | B68: Tracy House | C68: Female | D68: 27 | E68: 10 | F68: =VLOOKUP(Table6[[#This Row],[department_id]],departments[#All],2,FALSE) -> Product Operations | G68: =VLOOKUP(employees!$E68,departments[],3,FALSE) -> Product | H68: 20 | I68: =VLOOKUP(employees!$H68,locations[#All],3,FALSE) -> Singapore | J68: =_xlfn.XLOOKUP(Table6[[#This Row],[City]],locations[city],locations[Continent]) -> Asia | K68: Senior | L68: Bachelor | M68: 44004 | N68: On-site | O68: 3.43 | P68: 6.3 | Q68: 147750.11 | R68: 2653 | S68: =DATEDIF(employees!$M68, TODAY(), "y") -> 6 | T68: =VLOOKUP(employees!$H68,locations[#All],4,) -> 1.22 | U68: =employees!$Q68/employees!$T68 -> 121106.65
A69: 68 | B69: Carol Tucker | C69: Non-binary | D69: 36 | E69: 20 | F69: =VLOOKUP(Table6[[#This Row],[department_id]],departments[#All],2,FALSE) -> Recruiting | G69: =VLOOKUP(employees!$E69,departments[],3,FALSE) -> G&A | H69: 2 | I69: =VLOOKUP(employees!$H69,locations[#All],3,FALSE) -> New York | J69: =_xlfn.XLOOKUP(Table6[[#This Row],[City]],locations[city],locations[Continent]) -> North America | K69: Manager | L69: High School | M69: 44280 | N69: On-site | O69: 4.05 | P69: 9.1 | Q69: 154264.95 | R69: 1826 | S69: =DATEDIF(employees!$M69, TODAY(), "y") -> 5 | T69: =VLOOKUP(employees!$H69,locations[#All],4,) -> 1.3 | U69: =employees!$Q69/employees!$T69 -> 118665.35
A70: 69 | B70: James Brown | C70: Female | D70: 53 | E70: 25 | F70: =VLOOKUP(Table6[[#This Row],[department_id]],departments[#All],2,FALSE) -> Operations | G70: =VLOOKUP(employees!$E70,departments[],3,FALSE) -> Ops | H70: 9 | I70: =VLOOKUP(employees!$H70,locations[#All],3,FALSE) -> Amsterdam | J70: =_xlfn.XLOOKUP(Table6[[#This Row],[City]],locations[city],locations[Continent]) -> Europe | K70: Senior | L70: Bachelor | M70: 43075 | N70: Remote | O70: 2.92 | P70: 7.8 | Q70: 139128.18 | R70: 3194 | S70: =DATEDIF(employees!$M70, TODAY(), "y") -> 8 | T70: =VLOOKUP(employees!$H70,locations[#All],4,) -> 1.15 | U70: =employees!$Q70/employees!$T70 -> 120981.03
A71: 70 | B71: William Baker | C71: Female | D71: 62 | E71: 3 | F71: =VLOOKUP(Table6[[#This Row],[department_id]],departments[#All],2,FALSE) -> Data Engineering | G71: =VLOOKUP(employees!$E71,departments[],3,FALSE) -> Tech | H71: 16 | I71: =VLOOKUP(employees!$H71,locations[#All],3,FALSE) -> São Paulo | J71: =_xlfn.XLOOKUP(Table6[[#This Row],[City]],locations[city],locations[Continent]) -> South America | K71: Mid | L71: High School | M71: 44370 | N71: On-site | O71: 3.45 | P71: 7.4 | Q71: 100919.5 | R71: 2835 | S71: =DATEDIF(employees!$M71, TODAY(), "y") -> 5 | T71: =VLOOKUP(employees!$H71,locations[#All],4,) -> 0.8 | U71: =employees!$Q71/employees!$T71 -> 126149.38
... A74: 73 | B74: Brittney Phillips | C74: Male | D74: 21 | E74: 10 | F74: =VLOOKUP(Table6[[#This Row],[department_id]],departments[#All],2,FALSE) -> Product Operations | G74: =VLOOKUP(employees!$E74,departments[],3,FALSE) -> Product | H74: 15 | I74: =VLOOKUP(employees!$H74,locations[#All],3,FALSE) -> Cape Town | J74: =_xlfn.XLOOKUP(Table6[[#This Row],[City]],locations[city],locations[Continent]) -> Africa | K74: Manager | L74: PhD | M74: 45610 | N74: Hybrid | O74: 3.05 | P74: 5.8 | Q74: 122346.59 | R74: 3239 | S74: =DATEDIF(employees!$M74, TODAY(), "y") -> 1 | T74: =VLOOKUP(employees!$H74,locations[#All],4,) -> 0.7 | U74: =employees!$Q74/employees!$T74 -> 174780.84
A75: 74 | B75: Lauren Daniels | C75: Female | D75: 27 | E75: 3 | F75: =VLOOKUP(Table6[[#This Row],[department_id]],departments[#All],2,FALSE) -> Data Engineering | G75: =VLOOKUP(employees!$E75,departments[],3,FALSE) -> Tech | H75: 8 | I75: =VLOOKUP(employees!$H75,locations[#All],3,FALSE) -> Barcelona | J75: =_xlfn.XLOOKUP(Table6[[#This Row],[City]],locations[city],locations[Continent]) -> Europe | K75: Vp | L75: Bachelor | M75: 42569 | N75: On-site | O75: 4.65 | P75: 6.4 | Q75: 408984.32 | R75: Unknown | S75: =DATEDIF(employees!$M75, TODAY(), "y") -> 10 | T75: =VLOOKUP(employees!$H75,locations[#All],4,) -> 1.05 | U75: =employees!$Q75/employees!$T75 -> 389508.88
A76: 75 | B76: Amy Silva | C76: Female | D76: 32 | E76: 16 | F76: =VLOOKUP(Table6[[#This Row],[department_id]],departments[#All],2,FALSE) -> Content Marketing | G76: =VLOOKUP(employees!$E76,departments[],3,FALSE) -> GTM | H76: 16 | I76: =VLOOKUP(employees!$H76,locations[#All],3,FALSE) -> São Paulo | J76: =_xlfn.XLOOKUP(Table6[[#This Row],[City]],locations[city],locations[Continent]) -> South America | K76: Mid | L76: Master | M76: 42824 | N76: Hybrid | O76: 4.52 | P76: 9.1 | Q76: 50041.46 | R76: 1278 | S76: =DATEDIF(employees!$M76, TODAY(), "y") -> 9 | T76: =VLOOKUP(employees!$H76,locations[#All],4,) -> 0.8 | U76: =employees!$Q76/employees!$T76 -> 62551.825
A77: 76 | B77: Sarah Moore | C77: Female | D77: 20 | E77: 14 | F77: =VLOOKUP(Table6[[#This Row],[department_id]],departments[#All],2,FALSE) -> Sales Operations | G77: =VLOOKUP(employees!$E77,departments[],3,FALSE) -> GTM | H77: 11 | I77: =VLOOKUP(employees!$H77,locations[#All],3,FALSE) -> Bengaluru | J77: =_xlfn.XLOOKUP(Table6[[#This Row],[City]],locations[city],locations[Continent]) -> Asia | K77: Manager | L77: Bachelor | M77: 45799 | N77: On-site | O77: 3.85 | P77: 9.8 | Q77: 88461.29 | R77: 2909 | S77: =DATEDIF(employees!$M77, TODAY(), "y") -> 1 | T77: =VLOOKUP(employees!$H77,locations[#All],4,) -> 0.7 | U77: =employees!$Q77/employees!$T77 -> 126373.27
A78: 77 | B78: Angela Lopez | C78: Female | D78: 40 | E78: 18 | F78: =VLOOKUP(Table6[[#This Row],[department_id]],departments[#All],2,FALSE) -> Customer Support | G78: =VLOOKUP(employees!$E78,departments[],3,FALSE) -> GTM | H78: 16 | I78: =VLOOKUP(employees!$H78,locations[#All],3,FALSE) -> São Paulo | J78: =_xlfn.XLOOKUP(Table6[[#This Row],[City]],locations[city],locations[Continent]) -> South America | K78: Mid | L78: Master | M78: 44730 | N78: Remote | O78: 3.05 | P78: 6.8 | Q78: 50113.61 | R78: 1584 | S78: =DATEDIF(employees!$M78, TODAY(), "y") -> 4 | T78: =VLOOKUP(employees!$H78,locations[#All],4,) -> 0.8 | U78: =employees!$Q78/employees!$T78 -> 62642.012
A79: 78 | B79: Megan Young | C79: Female | D79: 62 | E79: 11 | F79: =VLOOKUP(Table6[[#This Row],[department_id]],departments[#All],2,FALSE) -> Design | G79: =VLOOKUP(employees!$E79,departments[],3,FALSE) -> Product | H79: 16 | I79: =VLOOKUP(employees!$H79,locations[#All],3,FALSE) -> São Paulo | J79: =_xlfn.XLOOKUP(Table6[[#This Row],[City]],locations[city],locations[Continent]) -> South America | K79: Senior | L79: Master | M79: 44763 | N79: Hybrid | O79: 2.85 | P79: 9.6 | Q79: 86565.5 | R79: 2989 | S79: =DATEDIF(employees!$M79, TODAY(), "y") -> 4 | T79: =VLOOKUP(employees!$H79,locations[#All],4,) -> 0.8 | U79: =employees!$Q79/employees!$T79 -> 108206.88
A80: 79 | B80: Steve Sanchez | C80: Male | D80: 53 | E80: 11 | F80: =VLOOKUP(Table6[[#This Row],[department_id]],departments[#All],2,FALSE) -> Design | G80: =VLOOKUP(employees!$E80,departments[],3,FALSE) -> Product | H80: 4 | I80: =VLOOKUP(employees!$H80,locations[#All],3,FALSE) -> Toronto | J80: =_xlfn.XLOOKUP(Table6[[#This Row],[City]],locations[city],locations[Continent]) -> North America | K80: Manager | L80: Master | M80: 45246 | N80: On-site | O80: 2.83 | P80: 9.2 | Q80: 199624.81 | R80: 3283 | S80: =DATEDIF(employees!$M80, TODAY(), "y") -> 2 | T80: =VLOOKUP(employees!$H80,locations[#All],4,) -> 1.1 | U80: =employees!$Q80/employees!$T80 -> 181477.1
A81: 80 | B81: Lisa Barnes | C81: Non-binary | D81: 25 | E81: 26 | F81: =VLOOKUP(Table6[[#This Row],[department_id]],departments[#All],2,FALSE) -> Procurement | G81: =VLOOKUP(employees!$E81,departments[],3,FALSE) -> Ops | H81: 9 | I81: =VLOOKUP(employees!$H81,locations[#All],3,FALSE) -> Amsterdam | J81: =_xlfn.XLOOKUP(Table6[[#This Row],[City]],locations[city],locations[Continent]) -> Europe | K81: Mid | L81: Master | M81: 44896 | N81: Remote | O81: 4.48 | P81: 6.8 | Q81: 90564.63 | R81: 1135 | S81: =DATEDIF(employees!$M81, TODAY(), "y") -> 3 | T81: =VLOOKUP(employees!$H81,locations[#All],4,) -> 1.15 | U81: =employees!$Q81/employees!$T81 -> 78751.852
A82: 81 | B82: Kelly Donovan | C82: Non-binary | D82: 24 | E82: 25 | F82: =VLOOKUP(Table6[[#This Row],[department_id]],departments[#All],2,FALSE) -> Operations | G82: =VLOOKUP(employees!$E82,departments[],3,FALSE) -> Ops | H82: 16 | I82: =VLOOKUP(employees!$H82,locations[#All],3,FALSE) -> São Paulo | J82: =_xlfn.XLOOKUP(Table6[[#This Row],[City]],locations[city],locations[Continent]) -> South America | K82: Manager | L82: Bachelor | M82: 41934 | N82: Hybrid | O82: 3.16 | P82: 6.1 | Q82: 105739.18 | R82: 3466 | S82: =DATEDIF(employees!$M82, TODAY(), "y") -> 11 | T82: =VLOOKUP(employees!$H82,locations[#All],4,) -> 0.8 | U82: =employees!$Q82/employees!$T82 -> 132173.97
...

Sheet departments
A1: department_id | B1: department | C1: category
A2: 1 | B2: Engineering | C2: Tech
A3: 2 | B3: Data Science | C3: Tech
A4: 3 | B4: Data Engineering | C4: Tech
A5: 4 | B5: ML Engineering | C5: Tech
A6: 5 | B6: Platform | C6: Tech
A7: 6 | B7: Security | C7: Tech
A8: 7 | B8: IT & Helpdesk | C8: Tech
A9: 8 | B9: QA & Testing | C9: Tech
A10: 9 | B10: Product Management | C10: Product
A11: 10 | B11: Product Operations | C11: Product
A12: 11 | B12: Design | C12: Product
A13: 12 | B13: UX Research | C13: Product
... A28: 27 | B28: Facilities | C28: Ops

Sheet locations
A1: location_id | B1: country | C1: city | D1: cost_index | E1: Continent
A2: 1 | B2: United States | C2: San Francisco | D2: 1.35 | E2: North America
A3: 2 | B3: United States | C3: New York | D3: 1.3 | E3: North America
A4: 3 | B4: United States | C4: Austin | D4: 1.05 | E4: North America
A5: 4 | B5: Canada | C5: Toronto | D5: 1.1 | E5: North America
A6: 5 | B6: United Kingdom | C6: London | D6: 1.25 | E6: Europe
A7: 6 | B7: Germany | C7: Berlin | D7: 1.1 | E7: Europe
A8: 7 | B8: France | C8: Paris | D8: 1.18 | E8: Europe
A9: 8 | B9: Spain | C9: Barcelona | D9: 1.05 | E9: Europe
A10: 9 | B10: Netherlands | C10: Amsterdam | D10: 1.15 | E10: Europe
A11: 10 | B11: Poland | C11: Warsaw | D11: 0.95 | E11: Europe
A12: 11 | B12: India | C12: Bengaluru | D12: 0.7 | E12: Asia
A13: 12 | B13: India | C13: Hyderabad | D13: 0.68 | E13: Asia
... A22: 21 | B22: Australia | C22: Sydney | D22: 1.15 | E22: Oceania

Sheet org_edges
A1: source_manager_id | B1: target_employee_id
A2: 2177 | B2: 1
A3: 2225 | B3: 2
A4: 43 | B4: 3
A5: 290 | B5: 4
A6: 1603 | B6: 5
A7: 2865 | B7: 6
A8: 778 | B8: 7
A9: 1834 | B9: 8
A10: 2497 | B10: 9
A11: 346 | B11: 10
A12: 2411 | B12: 11
A13: 873 | B13: 12
... A3435: 2623 | B3435: 3500

Sheet promotions
A1: employee_id | B1: promotion_date | C1: from_level | D1: to_level
A2: 2 | B2: 44702 | C2: Mid | D2: Senior
A3: 3 | B3: 45802 | C3: Senior | D3: Lead
A4: 6 | B4: 43782 | C4: Junior | D4: Mid
A5: 6 | B5: 43903 | C5: Mid | D5: Senior
A6: 6 | B6: 45237 | C6: Senior | D6: Lead
A7: 6 | B7: 45366 | C7: Lead | D7: Manager
A8: 7 | B8: 43609 | C8: Mid | D8: Senior
A9: 7 | B9: 44775 | C9: Senior | D9: Lead
A10: 8 | B10: 44065 | C10: Mid | D10: Senior
A11: 9 | B11: 44320 | C11: Mid | D11: Senior
A12: 15 | B12: 44271 | C12: Junior | D12: Mid
A13: 15 | B13: 45061 | C13: Mid | D13: Senior
... A2703: 3497 | B2703: 45863 | C2703: Mid | D2703: Senior

Sheet salaries_annual
A1: employee_id | B1: year | C1: seniority_level | D1: salary_usd | E1: Annual Salary Growth %
A2: 1 | B2: 2020 | C2: Intern | D2: 39578 | E2: =IF(A3=A2,(D3-D2)/D2,1) -> 0.026782556
A3: 1 | B3: 2021 | C3: Intern | D3: 40638 | E3: =IF(A4=A3,(D4-D3)/D3,1) -> 0.043161573
A4: 1 | B4: 2022 | C4: Intern | D4: 42392 | E4: =IF(A5=A4,(D5-D4)/D4,1) -> 0.052840159
A5: 1 | B5: 2023 | C5: Intern | D5: 44632 | E5: =IF(A6=A5,(D6-D5)/D5,1) -> 0.043511382
A6: 1 | B6: 2024 | C6: Intern | D6: 46574 | E6: =IF(A7=A6,(D7-D6)/D6,1) -> 0.065766307
A7: 1 | B7: 2025 | C7: Intern | D7: 49637 | E7: =IF(A8=A7,(D8-D7)/D7,1) -> 1
A8: 2 | B8: 2014 | C8: Mid | D8: 141489 | E8: =IF(A9=A8,(D9-D8)/D8,1) -> 0.02435525
A9: 2 | B9: 2015 | C9: Mid | D9: 144935 | E9: =IF(A10=A9,(D10-D9)/D9,1) -> 0.029475282
A10: 2 | B10: 2016 | C10: Mid | D10: 149207 | E10: =IF(A11=A10,(D11-D10)/D10,1) -> 0.031814861
A11: 2 | B11: 2017 | C11: Mid | D11: 153954 | E11: =IF(A12=A11,(D12-D11)/D11,1) -> 0.024124089
A12: 2 | B12: 2018 | C12: Mid | D12: 157668 | E12: =IF(A13=A12,(D13-D12)/D12,1) -> 0.032612832
A13: 2 | B13: 2019 | C13: Mid | D13: 162810 | E13: =IF(A14=A13,(D14-D13)/D13,1) -> 0.029199681
... A22853: 3500 | B22853: 2025 | C22853: Mid | D22853: 123501 | E22853: =IF(A22854=A22853,(D22854-D22853)/D22853,1) -> 1

Sheet Pivot Tables
A1: Employee Count by Department Category
A2: department_category | B2: Total
A3: G&A | B3: 805
A4: GTM | B4: 795
A5: Ops | B5: 389
A6: Product | B6: 487
A7: Tech | B7: 1024
A8: Grand Total | B8: 3500
A16: Average Salary by Department
A17: department_category | B17: department_name | C17: Total
A18: G&A | B18: Accounting | C18: 12518336
B19: Administration | C19: 8168376.2
B20: Finance | C20: 16962474
B21: Human Resources | C21: 11950230
B22: Legal | C22: 22717858
B23: Recruiting | C23: 11423612
A24: G&A Total | C24: 83740885
A25: GTM | B25: Content Marketing | C25: 9157875.9
B26: Customer Success | C26: 10301433
B27: Customer Support | C27: 7095206.2
B28: Marketing | C28: 15311086
B29: Sales | C29: 12409856
B30: Sales Operations | C30: 13927324
A31: GTM Total | C31: 68202781
A32: Ops | B32: Facilities | C32: 8712400.7
B33: Operations | C33: 13173264
B34: Procurement | C34: 13686251
A35: Ops Total | C35: 35571916
A36: Product | B36: Design | C36: 12968197
B37: Product Management | C37: 17230181
B38: Product Operations | C38: 13675869
B39: UX Research | C39: 16237613
A40: Product Total | C40: 60111860
A41: Tech | B41: Data Engineering | C41: 20506812
B42: Data Science | C42: 17683254
B43: Engineering | C43: 19781047
B44: IT & Helpdesk | C44: 10921895
B45: ML Engineering | C45: 19233314
B46: Platform | C46: 22436198
B47: QA & Testing | C47: 12874105
...
